WARNING: Error in initializing MVAPICH2 ptmalloc library.Continuing without InfiniBand registration cache support.
Traceback (most recent call last):
  File "/opt/scipy/3.6/lib/python3.6/site-packages/pandas/core/indexes/base.py", line 3078, in get_loc
    return self._engine.get_loc(key)
  File "pandas/_libs/index.pyx", line 140, in pandas._libs.index.IndexEngine.get_loc
  File "pandas/_libs/index.pyx", line 162, in pandas._libs.index.IndexEngine.get_loc
  File "pandas/_libs/hashtable_class_helper.pxi", line 1492, in pandas._libs.hashtable.PyObjectHashTable.get_item
  File "pandas/_libs/hashtable_class_helper.pxi", line 1500, in pandas._libs.hashtable.PyObjectHashTable.get_item
KeyError: '30yrs_10prc'

During handling of the above exception, another exception occurred:

Traceback (most recent call last):
  File "makeLRinteractionPlot.py", line 273, in <module>
    factor_mapping(all_IDs[i])
  File "makeLRinteractionPlot.py", line 196, in factor_mapping
    pseudo_r_scores = all_pseudo_r_scores[str(int(historic_percents[h]))+'yrs_'+str(magnitudes[h])+'prc'].values
  File "/opt/scipy/3.6/lib/python3.6/site-packages/pandas/core/frame.py", line 2688, in __getitem__
    return self._getitem_column(key)
  File "/opt/scipy/3.6/lib/python3.6/site-packages/pandas/core/frame.py", line 2695, in _getitem_column
    return self._get_item_cache(key)
  File "/opt/scipy/3.6/lib/python3.6/site-packages/pandas/core/generic.py", line 2489, in _get_item_cache
    values = self._data.get(item)
  File "/opt/scipy/3.6/lib/python3.6/site-packages/pandas/core/internals.py", line 4115, in get
    loc = self.items.get_loc(item)
  File "/opt/scipy/3.6/lib/python3.6/site-packages/pandas/core/indexes/base.py", line 3080, in get_loc
    return self._engine.get_loc(self._maybe_cast_indexer(key))
  File "pandas/_libs/index.pyx", line 140, in pandas._libs.index.IndexEngine.get_loc
  File "pandas/_libs/index.pyx", line 162, in pandas._libs.index.IndexEngine.get_loc
  File "pandas/_libs/hashtable_class_helper.pxi", line 1492, in pandas._libs.hashtable.PyObjectHashTable.get_item
  File "pandas/_libs/hashtable_class_helper.pxi", line 1500, in pandas._libs.hashtable.PyObjectHashTable.get_item
KeyError: '30yrs_10prc'
Warning: Maximum number of iterations has been exceeded.
         Current function value: inf
         Iterations: 35
/home/jdq2101/.local/lib/python3.6/site-packages/statsmodels/discrete/discrete_model.py:1736: RuntimeWarning: overflow encountered in exp
  return 1/(1+np.exp(-X))
/home/jdq2101/.local/lib/python3.6/site-packages/statsmodels/discrete/discrete_model.py:1789: RuntimeWarning: divide by zero encountered in log
  return np.sum(np.log(self.cdf(q*np.dot(X,params))))
Traceback (most recent call last):
  File "makeLRinteractionPlot.py", line 273, in <module>
    factor_mapping(all_IDs[i])
  File "makeLRinteractionPlot.py", line 218, in factor_mapping
    result = fitLogit(dta, [all_predictors[i] for i in [0,1]])
  File "makeLRinteractionPlot.py", line 133, in fitLogit
    result = logit.fit() 
  File "/home/jdq2101/.local/lib/python3.6/site-packages/statsmodels/discrete/discrete_model.py", line 1902, in fit
    disp=disp, callback=callback, **kwargs)
  File "/home/jdq2101/.local/lib/python3.6/site-packages/statsmodels/discrete/discrete_model.py", line 217, in fit
    disp=disp, callback=callback, **kwargs)
  File "/home/jdq2101/.local/lib/python3.6/site-packages/statsmodels/base/model.py", line 477, in fit
    Hinv = np.linalg.inv(-retvals['Hessian']) / nobs
  File "<__array_function__ internals>", line 6, in inv
  File "/opt/python/lib/python3.6/site-packages/numpy-1.17.0-py3.6-linux-x86_64.egg/numpy/linalg/linalg.py", line 551, in inv
    ainv = _umath_linalg.inv(a, signature=signature, extobj=extobj)
  File "/opt/python/lib/python3.6/site-packages/numpy-1.17.0-py3.6-linux-x86_64.egg/numpy/linalg/linalg.py", line 97, in _raise_linalgerror_singular
    raise LinAlgError("Singular matrix")
numpy.linalg.LinAlgError: Singular matrix
Warning: Maximum number of iterations has been exceeded.
         Current function value: inf
         Iterations: 35
/home/jdq2101/.local/lib/python3.6/site-packages/statsmodels/discrete/discrete_model.py:1736: RuntimeWarning: overflow encountered in exp
  return 1/(1+np.exp(-X))
/home/jdq2101/.local/lib/python3.6/site-packages/statsmodels/discrete/discrete_model.py:1789: RuntimeWarning: divide by zero encountered in log
  return np.sum(np.log(self.cdf(q*np.dot(X,params))))
Traceback (most recent call last):
  File "makeLRinteractionPlot.py", line 273, in <module>
    factor_mapping(all_IDs[i])
  File "makeLRinteractionPlot.py", line 218, in factor_mapping
    result = fitLogit(dta, [all_predictors[i] for i in [0,1]])
  File "makeLRinteractionPlot.py", line 133, in fitLogit
    result = logit.fit() 
  File "/home/jdq2101/.local/lib/python3.6/site-packages/statsmodels/discrete/discrete_model.py", line 1902, in fit
    disp=disp, callback=callback, **kwargs)
  File "/home/jdq2101/.local/lib/python3.6/site-packages/statsmodels/discrete/discrete_model.py", line 217, in fit
    disp=disp, callback=callback, **kwargs)
  File "/home/jdq2101/.local/lib/python3.6/site-packages/statsmodels/base/model.py", line 477, in fit
    Hinv = np.linalg.inv(-retvals['Hessian']) / nobs
  File "<__array_function__ internals>", line 6, in inv
  File "/opt/python/lib/python3.6/site-packages/numpy-1.17.0-py3.6-linux-x86_64.egg/numpy/linalg/linalg.py", line 551, in inv
    ainv = _umath_linalg.inv(a, signature=signature, extobj=extobj)
  File "/opt/python/lib/python3.6/site-packages/numpy-1.17.0-py3.6-linux-x86_64.egg/numpy/linalg/linalg.py", line 97, in _raise_linalgerror_singular
    raise LinAlgError("Singular matrix")
numpy.linalg.LinAlgError: Singular matrix
Optimization terminated successfully.
         Current function value: 0.129906
         Iterations 11
Warning: Maximum number of iterations has been exceeded.
         Current function value: inf
         Iterations: 35
/home/jdq2101/.local/lib/python3.6/site-packages/statsmodels/discrete/discrete_model.py:1736: RuntimeWarning: overflow encountered in exp
  return 1/(1+np.exp(-X))
/home/jdq2101/.local/lib/python3.6/site-packages/statsmodels/discrete/discrete_model.py:1789: RuntimeWarning: divide by zero encountered in log
  return np.sum(np.log(self.cdf(q*np.dot(X,params))))
Traceback (most recent call last):
  File "makeLRinteractionPlot.py", line 273, in <module>
    factor_mapping(all_IDs[i])
  File "makeLRinteractionPlot.py", line 218, in factor_mapping
    result = fitLogit(dta, [all_predictors[i] for i in [0,1]])
  File "makeLRinteractionPlot.py", line 133, in fitLogit
    result = logit.fit() 
  File "/home/jdq2101/.local/lib/python3.6/site-packages/statsmodels/discrete/discrete_model.py", line 1902, in fit
    disp=disp, callback=callback, **kwargs)
  File "/home/jdq2101/.local/lib/python3.6/site-packages/statsmodels/discrete/discrete_model.py", line 217, in fit
    disp=disp, callback=callback, **kwargs)
  File "/home/jdq2101/.local/lib/python3.6/site-packages/statsmodels/base/model.py", line 477, in fit
    Hinv = np.linalg.inv(-retvals['Hessian']) / nobs
  File "<__array_function__ internals>", line 6, in inv
  File "/opt/python/lib/python3.6/site-packages/numpy-1.17.0-py3.6-linux-x86_64.egg/numpy/linalg/linalg.py", line 551, in inv
    ainv = _umath_linalg.inv(a, signature=signature, extobj=extobj)
  File "/opt/python/lib/python3.6/site-packages/numpy-1.17.0-py3.6-linux-x86_64.egg/numpy/linalg/linalg.py", line 97, in _raise_linalgerror_singular
    raise LinAlgError("Singular matrix")
numpy.linalg.LinAlgError: Singular matrix
/home/jdq2101/.local/lib/python3.6/site-packages/statsmodels/discrete/discrete_model.py:1736: RuntimeWarning: overflow encountered in exp
  return 1/(1+np.exp(-X))
/home/jdq2101/.local/lib/python3.6/site-packages/statsmodels/discrete/discrete_model.py:1789: RuntimeWarning: divide by zero encountered in log
  return np.sum(np.log(self.cdf(q*np.dot(X,params))))
Optimization terminated successfully.
         Current function value: 0.327866
         Iterations 8
Optimization terminated successfully.
         Current function value: 0.277085
         Iterations 9
Optimization terminated successfully.
         Current function value: 0.200833
         Iterations 10
Optimization terminated successfully.
         Current function value: 0.045447
         Iterations 15
Warning: Maximum number of iterations has been exceeded.
         Current function value: inf
         Iterations: 35
Traceback (most recent call last):
  File "makeLRinteractionPlot.py", line 273, in <module>
    factor_mapping(all_IDs[i])
  File "makeLRinteractionPlot.py", line 218, in factor_mapping
    result = fitLogit(dta, [all_predictors[i] for i in [0,1]])
  File "makeLRinteractionPlot.py", line 133, in fitLogit
    result = logit.fit() 
  File "/home/jdq2101/.local/lib/python3.6/site-packages/statsmodels/discrete/discrete_model.py", line 1902, in fit
    disp=disp, callback=callback, **kwargs)
  File "/home/jdq2101/.local/lib/python3.6/site-packages/statsmodels/discrete/discrete_model.py", line 217, in fit
    disp=disp, callback=callback, **kwargs)
  File "/home/jdq2101/.local/lib/python3.6/site-packages/statsmodels/base/model.py", line 477, in fit
    Hinv = np.linalg.inv(-retvals['Hessian']) / nobs
  File "<__array_function__ internals>", line 6, in inv
  File "/opt/python/lib/python3.6/site-packages/numpy-1.17.0-py3.6-linux-x86_64.egg/numpy/linalg/linalg.py", line 551, in inv
    ainv = _umath_linalg.inv(a, signature=signature, extobj=extobj)
  File "/opt/python/lib/python3.6/site-packages/numpy-1.17.0-py3.6-linux-x86_64.egg/numpy/linalg/linalg.py", line 97, in _raise_linalgerror_singular
    raise LinAlgError("Singular matrix")
numpy.linalg.LinAlgError: Singular matrix
[comet-04-63.sdsc.edu:mpispawn_0][child_handler] MPI process (rank: 0, pid: 28410) exited with status 1
[comet-04-63.sdsc.edu:mpispawn_0][child_handler] MPI process (rank: 3, pid: 28413) exited with status 1
[comet-04-63.sdsc.edu:mpispawn_0][child_handler] MPI process (rank: 2, pid: 28412) exited with status 1
[comet-04-63.sdsc.edu:mpispawn_0][child_handler] MPI process (rank: 4, pid: 28414) exited with status 1
[comet-04-63.sdsc.edu:mpispawn_0][child_handler] MPI process (rank: 1, pid: 28411) exited with status 1
